Workbook

Sheet taustatiedot
B2: Pääluokka | C2: Kustannus/tulo | D2: Automatisoitu vai syöttö | E2: Mistä kustannus/tulo on haettu | F2: Tulevaisuuden kehitysidea
B3: Talonrakentaminen | C3: Esirakentaminen | D3: Syöttö | E3: Tieto kysytään KITIA:lta
B4: Talonrakentaminen | C4: Maaperän kunnostaminen | D4: Syöttö | E4: Tieto kysytään KITIA:lta
B5: Talonrakentaminen | C5: Rakenteiden muutokset ja purut | D5: Syöttö | E5: Tieto kysytään KITIA:lta
B6: Talonrakentaminen | C6: Talonrakentaminen | D6: Syöttö | E6: Tieto kysytään KITIA:lta, käytetään kaavasuunnitelman kerrosalaa
B7: Talonrakentaminen | C7: Palvelutilarakennusten rakentaminen | D7: Syöttö | E7: Tieto kysytään KITIA:lta
B8: Talonrakentaminen | C8: Palvelutilarakennusten kunnossapito | D8: Syöttö
B9: Infrarakentaminen | C9: Esirakentaminen | D9: Syöttö | E9: Ihku-laskentapalvelussa laskettu | F9: Ihku-kehitys ja rajapinnan kehittäminen
B10: Infrarakentaminen | C10: Maaperän kunnostaminen | D10: Syöttö | E10: Ihku-laskentapalvelussa laskettu | F10: Ihku-kehitys ja rajapinnan kehittäminen
B11: Infrarakentaminen | C11: Rakenteiden muutokset ja purut | D11: Syöttö | E11: Ihku-laskentapalvelussa laskettu | F11: Ihku-kehitys ja rajapinnan kehittäminen
B12: Infrarakentaminen | C12: Melusuojat | D12: Syöttö | E12: Ihku-laskentapalvelussa laskettu | F12: Ihku-kehitys ja rajapinnan kehittäminen
B13: Infrarakentaminen | C13: Ympäristösuojat | D13: Syöttö | E13: Ihku-laskentapalvelussa laskettu | F13: Ihku-kehitys ja rajapinnan kehittäminen
B14: Infrarakentaminen | C14: Tie- ja katuverkon rakentaminen | D14: Syöttö | E14: Ihku-laskentapalvelussa laskettu | F14: Ihku-kehitys ja rajapinnan kehittäminen
B15: Infrarakentaminen | C15: Kunnallistekniikan rakentaminen | D15: Syöttö | E15: Ihku-laskentapalvelussa laskettu | F15: Ihku-kehitys ja rajapinnan kehittäminen
B16: Infrarakentaminen | C16: Vesihuolto | D16: Syöttö | E16: Ihku-laskentapalvelussa laskettu | F16: Ihku-kehitys ja rajapinnan kehittäminen
B17: Infrarakentaminen | C17: Energiahuolto | D17: Syöttö | E17: Ihku-laskentapalvelussa laskettu | F17: Ihku-kehitys ja rajapinnan kehittäminen
B18: Infrarakentaminen | C18: Puistojen ja yleisten alueiden rakentaminen | D18: Syöttö | E18: Ihku-laskentapalvelussa laskettu | F18: Ihku-kehitys ja rajapinnan kehittäminen
B19: Infrarakentaminen | C19: Sillat (taitorakenteet) | D19: Syöttö | E19: Ihku-laskentapalvelussa laskettu | F19: Ihku-kehitys ja rajapinnan kehittäminen
B20: Infrarakentaminen | C20: Raitiotie | D20: Syöttö | E20: Raitiotieallianssilta | F20: Ihku-kehitys ja rajapinnan kehittäminen
B21: Infrarakentaminen | C21: Pysäköinti | D21: Syöttö | E21: Pysäköinnin suunnitelmista | F21: Ihku-kehitys ja rajapinnan kehittäminen
B22: Infrarakentaminen | C22: Tie- ja katuverkon kunnossapito | D22: Syöttö | F22: Ihku-kehitys ja rajapinnan kehittäminen
B23: Infrarakentaminen | C23: Kunnallistekniikan kunnossapito | D23: Syöttö | F23: Ihku-kehitys ja rajapinnan kehittäminen
B24: Infrarakentaminen | C24: Puistojen ja yleisten alueiden kunnossapito | D24: Syöttö | F24: Ihku-kehitys ja rajapinnan kehittäminen
B25: Maanhankinta | C25: Maan osto | D25: Syöttö | E25: Kaupungin maanhankintapäällikön konsultointi | F25: MML:n kansallinen kauppahintatilasto
B26: Maanhankinta | C26: Maan lunastus | D26: Syöttö | E26: Kaupungin maanhankintapäällikön konsultointi | F26: MML:n kansallinen kauppahintatilasto
B27: Maan myynti tai vuokraus | C27: Maan myynti | D27: Syöttö | E27: Vyöhykehinnastot (KITIA) | F27: Vyöhyketaulukot avoimesti kaupungilla sisällä saataviksi, jotta voidaan automatisoida
B28: Maan myynti tai vuokraus | C28: Maan vuokraus
B29: Maankäyttötulot | C29: Maankäyttömaksut | D29: Syöttö | E29: Tieto kysytään KITIA:lta
B30: Verotulot | C30: Kunnallisvero
B31: Verotulot | C31: Kiinteistövero
B32: Käyttömaksut | C32: Käyttömaksut, vesi | D32: Syöttö | E32: Tampereen vesi, hinnasto (https://www.tampereenvesi.fi/hinnasto/?floor_area=100&waste=1&water=1&usage=1%2C6#lomake-1) | F32: Vesilaitoyhdistyksen tilastotieto kuntien maksuista hyödynnettäväksi rakenteelliseen muotoon?
B33: Käyttömaksut | C33: Käyttömaksut, energia | D33: Syöttö | F33: Vesilaitoyhdistyksen tilastotieto kuntien maksuista hyödynnettäväksi rakenteelliseen muotoon?
B34: Käyttömaksut | C34: Liittymismaksut, vesi | D34: Syöttö | E34: Tampereen vesi, liittymismaksulaskuri 2026 | F34: Energiateollisuuden tilastotieto hinnastoista hyödynnettäväksi rakenteelliseen muotoon?
B35: Käyttömaksut | C35: Liittymismaksut, energia | D35: Syöttö | E35: Tampereen energia, kaukolämmön hinnastot (https://www.tampereenenergia.fi/energiaratkaisut/hinnastot/#lahilampoliittymismaksut) | F35: Energiateollisuuden tilastotieto hinnastoista hyödynnettäväksi rakenteelliseen muotoon?

Sheet data
B1: Perustiedot | D1: Verotus | G1: Maan myynti ja vuokraus | M1: Päästöt
B3: Pääluokka | D3: Tyyppi | E3: % | G3: numero | H3: vyöhyke | I3: keskiarvohinta (€/k-m2) | J3: minimi (€/k-m2) | K3: maksimi (€/k-m2) | M3: Resource Id | N3: Version | O3: Name EN | P3: Name FI | Q3: Name SV | R3: Property Unit Code | S3: GWP_A1-A3 Total | T3: GWP_A1-A3 fossil conservative | U3: GWP_B4 | V3: GWP_C3 | W3: GWP_C4 | X3: Base Categories EN | Y3: Base Categories FI | Z3: Base Categories SV | AA3: Updated Date | AB3: CO2data URL
B4: Talonrakentaminen | D4: Maapohjan yleinen kiinteistövero-% | E4: 1.3 | G4: 1 | H4: 1. Keskusta | I4: 900 | J4: 800 | K4: 1200 | M4: 7000000917 | N4: 1.01.006 | O4: Office building, health center | P4: Toimistorakennus, terveyskeskus | Q4: Kontorsbyggnader, hälsocentraler | R4: kg CO2e/m2 | S4: 110 | T4: 110 | U4: 97 | X4: Building services | Y4: Talotekniikka | Z4: Husteknik | AA4: 2025-06-04 | AB4: https://co2data.fi/rakentaminen/#en_id7000000917
B5: Infrarakentaminen | D5: Rakennusten yleinen kiinteistövero-% | E5: 1.25 | G5: 2 | H5: 2. Onkiniemi - Ranta-Tampella - Lapinniemi | I5: 1000 | J5: 800 | K5: 1300 | M5: 7000000919 | N5: 1.01.006 | O5: Commercial building | P5: Liikerakennus | Q5: Affärsbyggnader | R5: kg CO2e/m2 | S5: 130 | T5: 130 | U5: 119 | X5: Building services | Y5: Talotekniikka | Z5: Husteknik | AA5: 2025-06-04 | AB5: https://co2data.fi/rakentaminen/#en_id7000000919
B6: Maanhankinta | D6: Vakituisen asunnon kiinteistövero-% | E6: 0.65 | G6: 3 | H6: 3. Ratina - Viinikanlahti | I6: 1000 | J6: 800 | K6: 1300 | M6: 7000000920 | N6: 1.01.006 | O6: Accommodation building | P6: Majoitusliikerakennus | Q6: Inkvarteringsbyggnader | R6: kg CO2e/m2 | S6: 134 | T6: 134 | U6: 88 | X6: Building services | Y6: Talotekniikka | Z6: Husteknik | AA6: 2025-06-04 | AB6: https://co2data.fi/rakentaminen/#en_id7000000920
B7: Maan myynti tai vuokraus | D7: Muun asuinrakennuksen kiinteistövero-% | E7: 1.1 | G7: 4 | H7: 4. Pyynikki | I7: 1000 | J7: 800 | K7: 1300 | M7: 7000000921 | N7: 1.01.006 | O7: Education building, daycare centre | P7: Opetusrakennus, päiväkoti | Q7: Undervisningsbyggnader, daghem | R7: kg CO2e/m2 | S7: 128 | T7: 128 | U7: 94 | X7: Building services | Y7: Talotekniikka | Z7: Husteknik | AA7: 2025-06-04 | AB7: https://co2data.fi/rakentaminen/#en_id7000000921
B8: Maankäyttötulot | D8: Yleishyodyllisen yhteisön kiinteistövero-% | E8: 0.4 | G8: 5 | H8: 5. Kaleva | I8: 700 | J8: 500 | K8: 1000 | M8: 7000000922 | N8: 1.01.006 | O8: Apartment building | P8: Asuinkerrostalo | Q8: Flervåningsbostadshus | R8: kg CO2e/m2 | S8: 61 | T8: 61 | U8: 13 | X8: Building services | Y8: Talotekniikka | Z8: Husteknik | AA8: 2025-06-04 | AB8: https://co2data.fi/rakentaminen/#en_id7000000922
B9: Verotulot | D9: Rakentamattoman tontin kiinteistövero-% | E9: 5 | G9: 6 | H9: 6. Villilä - Hiedanranta - Pispala - Santalahti | I9: 700 | J9: 500 | K9: 1000 | M9: 7000001035 | N9: 1.01.006 | O9: Small apartment building | P9: Pieni asuinrakennus | Q9: Små bostadshus | R9: kg CO2e/m2 | S9: 50 | T9: 50 | U9: 9 | X9: Building services | Y9: Talotekniikka | Z9: Husteknik | AA9: 2025-06-04 | AB9: https://co2data.fi/rakentaminen/#en_id7000001035
B10: Verkostomaksut | D10: Voimalaitosrakennuksen kiinteistövero-% | E10: 3 | G10: 7 | H10: 7. Rahola - Lamminpää - Lielahti - Niemenranta | I10: 400 | J10: 300 | K10: 500 | M10: 7000001037 | N10: 1.01.006 | O10: Building for sports and physical exercise | P10: Liikuntahalli lukuun ottamatta uimahalliaja jäähallia | Q10: Idrottshallar med undantag av simhallaroch ishallar | R10: kg CO2e/m2 | S10: 83 | T10: 83 | U10: 81 | X10: Building services | Y10: Talotekniikka | Z10: Husteknik | AA10: 2025-06-04 | AB10: https://co2data.fi/rakentaminen/#en_id7000001037
G11: 8 | H11: 8. Länsi-Tampere (Haukiluoma - Tesoma - Lentävänniemi) | I11: 280 | J11: 250 | K11: 400 | M11: 7000001038 | N11: 1.01.006 | O11: Hospital | P11: Sairaala | Q11: Sjukhus | R11: kg CO2e/m2 | S11: 120 | T11: 120 | U11: 70 | X11: Building services | Y11: Talotekniikka | Z11: Husteknik | AA11: 2025-06-04 | AB11: https://co2data.fi/rakentaminen/#en_id7000001038
B12: Osapuoli | D12: Kiinteistöveron määrän laskukaava | E12: € | G12: 9 | H12: 9. Härmälänranta - Järvensivu | I12: 500 | J12: 300 | K12: 900 | M12: 7000001087 | N12: 1.01.006 | O12: Other building, warehouse | P12: Muu rakennus, varastorakennus | Q12: Övriga byggnader, lagerbyggnader | R12: kg CO2e/m2 | S12: 84 | T12: 84 | U12: 66 | X12: Building services | Y12: Talotekniikka | Z12: Husteknik | AA12: 2025-06-04 | AB12: https://co2data.fi/rakentaminen/#en_id7000001087
B13: Tampereen kaupunki | D13: neliökohtainen arvo (vvm) | E13: 691.62 | G13: 10 | H13: 10. Koivistonkylä - Pohjois-Hervanta - Pappila | I13: 400 | J13: 300 | K13: 500 | M13: 7000001088 | N13: 1.01.006 | O13: Other building, indoor ice rink | P13: Muu rakennus, jäähalli | Q13: Övriga byggnader, ishallar | R13: kg CO2e/m2 | S13: 72 | T13: 72 | U13: 74 | X13: Building services | Y13: Talotekniikka | Z13: Husteknik | AA13: 2025-06-04 | AB13: https://co2data.fi/rakentaminen/#en_id7000001088
B14: Tampereen vesi | D14: neliöt | E14: 150 | G14: 11 | H14: 11. Etelä-Tampere (Lahdesjärvi - Hervanta - Olkahinen) | I14: 280 | J14: 250 | K14: 400 | M14: 7000001089 | N14: 1.01.006 | O14: Other building, transport and communications building | P14: Muu rakennus, liikenteen rakennus | Q14: Övriga byggnader, trafikbyggnader | R14: kg CO2e/m2 | S14: 109 | T14: 109 | U14: 83 | X14: Building services | Y14: Talotekniikka | Z14: Husteknik | AA14: 2025-06-04 | AB14: https://co2data.fi/rakentaminen/#en_id7000001089
B15: Tampereen energia | D15: jälleenhankinta-arvo | E15: =E14*E13 -> 103743 | M15: 7000001090 | N15: 1.01.006 | O15: Other building, indoor swimming pool | P15: Muu rakennus, uimahalli | Q15: Övriga byggnader, simhallar | R15: kg CO2e/m2 | S15: 103 | T15: 103 | U15: 76 | X15: Building services | Y15: Talotekniikka | Z15: Husteknik | AA15: 2025-06-04 | AB15: https://co2data.fi/rakentaminen/#en_id7000001090
B16: Raitiotie-allianssi | D16: ikäalennusprosentti/v | E16: 1.25 | G16: Vyöhyke | H16: Vyöhykenimi | I16: € / k-m2 | J16: Kerrosneliömetrit | K16: Tulo
B17: Muu | D17: rakennuksen ikä vuosina | E17: 26 | G17: 4 | H17: =IF(G17=1,$H$4,IF(G17=2,$H$5,IF(G17=3,$H$6,IF(G17=4,$H$7,IF(G17=5,$H$8,IF(G17=6,$CH$9,IF(G17=7,$H$10,IF(G17=8,$H$11,IF(G17=9,$H$12,IF(G17=10,$H$13,IF(G17=11,$H$14,0))))))))))) -> 4. Pyynikki | I17: =IF(G17=1,900,IF(G17=2,1000,IF(G17=3,1000,IF(G17=4,1000,IF(G17=5,700,IF(G17=6,700,IF(G17=7,400,IF(G17=8,280,IF(G17=9,500,IF(G17=10,400,IF(G17=11,280,0))))))))))) -> 1000 | J17: 300 | K17: =J17*I17 -> 300000
D18: ikäalennus prosentteina | E18: =E17*E16 -> 32.5 | G18: 3 | H18: =IF(G18=1,$H$4,IF(G18=2,$H$5,IF(G18=3,$H$6,IF(G18=4,$H$7,IF(G18=5,$H$8,IF(G18=6,$CH$9,IF(G18=7,$H$10,IF(G18=8,$H$11,IF(G18=9,$H$12,IF(G18=10,$H$13,IF(G18=11,$H$14,0))))))))))) -> 3. Ratina - Viinikanlahti | I18: =IF(G18=1,900,IF(G18=2,1000,IF(G18=3,1000,IF(G18=4,1000,IF(G18=5,700,IF(G18=6,700,IF(G18=7,400,IF(G18=8,280,IF(G18=9,500,IF(G18=10,400,IF(G18=11,280,0))))))))))) -> 1000 | J18: 250 | K18: =J18*I18 -> 250000
D19: ikäalennus euroina | E19: =E18*(E15/100) -> 33716.475 | G19: 5 | H19: =IF(G19=1,$H$4,IF(G19=2,$H$5,IF(G19=3,$H$6,IF(G19=4,$H$7,IF(G19=5,$H$8,IF(G19=6,$CH$9,IF(G19=7,$H$10,IF(G19=8,$H$11,IF(G19=9,$H$12,IF(G19=10,$H$13,IF(G19=11,$H$14,0))))))))))) -> 5. Kaleva | I19: =IF(G19=1,900,IF(G19=2,1000,IF(G19=3,1000,IF(G19=4,1000,IF(G19=5,700,IF(G19=6,700,IF(G19=7,400,IF(G19=8,280,IF(G19=9,500,IF(G19=10,400,IF(G19=11,280,0))))))))))) -> 700 | J19: 500 | K19: =J19*I19 -> 350000
D20: verotusarvo | E20: =E15-E19 -> 70026.525 | G20: 2 | H20: =IF(G20=1,$H$4,IF(G20=2,$H$5,IF(G20=3,$H$6,IF(G20=4,$H$7,IF(G20=5,$H$8,IF(G20=6,$CH$9,IF(G20=7,$H$10,IF(G20=8,$H$11,IF(G20=9,$H$12,IF(G20=10,$H$13,IF(G20=11,$H$14,0))))))))))) -> 2. Onkiniemi - Ranta-Tampella - Lapinniemi | I20: =IF(G20=1,900,IF(G20=2,1000,IF(G20=3,1000,IF(G20=4,1000,IF(G20=5,700,IF(G20=6,700,IF(G20=7,400,IF(G20=8,280,IF(G20=9,500,IF(G20=10,400,IF(G20=11,280,0))))))))))) -> 1000 | J20: 200 | K20: =J20*I20 -> 200000
D21: veroprosentti | E21: 1.25 | G21: 4 | H21: =IF(G21=1,$H$4,IF(G21=2,$H$5,IF(G21=3,$H$6,IF(G21=4,$H$7,IF(G21=5,$H$8,IF(G21=6,$CH$9,IF(G21=7,$H$10,IF(G21=8,$H$11,IF(G21=9,$H$12,IF(G21=10,$H$13,IF(G21=11,$H$14,0))))))))))) -> 4. Pyynikki | I21: =IF(G21=1,900,IF(G21=2,1000,IF(G21=3,1000,IF(G21=4,1000,IF(G21=5,700,IF(G21=6,700,IF(G21=7,400,IF(G21=8,280,IF(G21=9,500,IF(G21=10,400,IF(G21=11,280,0))))))))))) -> 1000 | J21: 700 | K21: =J21*I21 -> 700000
D22: veron määrä euroina | E22: =E20*(E21/100) -> 875.33156 | G22: 4 | H22: =IF(G22=1,$H$4,IF(G22=2,$H$5,IF(G22=3,$H$6,IF(G22=4,$H$7,IF(G22=5,$H$8,IF(G22=6,$CH$9,IF(G22=7,$H$10,IF(G22=8,$H$11,IF(G22=9,$H$12,IF(G22=10,$H$13,IF(G22=11,$H$14,0))))))))))) -> 4. Pyynikki | I22: =IF(G22=1,900,IF(G22=2,1000,IF(G22=3,1000,IF(G22=4,1000,IF(G22=5,700,IF(G22=6,700,IF(G22=7,400,IF(G22=8,280,IF(G22=9,500,IF(G22=10,400,IF(G22=11,280,0))))))))))) -> 1000 | J22: 500 | K22: =J22*I22 -> 500000
D24: Kunnallisvero | E24: Luku | G24: VUOKRAUS tuotto-odotusta: arvio tulevasta arvonnoususta ja käyttötarkoituksesta
D25: Kunnallivero (%) | E25: 7.6 | G25: Tarkoitus | H25: Prosentti | I25: Desimaali
D26: Mediaanitulo | E26: 30000 | G26: Asuminen | H26: 4 | I26: 0.04
D27: Oletettu uusi asukasmäärä | E27: 1000 | G27: Muut | H27: 6 | I27: 0.06
D28: Kunnallisvero euroina | E28: =(E25/100)*E26*E27 -> 2280000
G29: Tekijä | H29: Arvo
D30: Kiinteistöveron perusarvot ilman huomioita | E30: € | G30: Uusi arvo | H30: 11
D31: Rakennustyyppi | E31: Neliökohtainen perusarvo | G31: Nykyinen arvo | H31: 9
D32: Pientalo | E32: 769.04 | G32: Purkukustannukset | H32: 2
D33: Asuinkerrostalo | E33: 769.04 | G33: Arvonnousu | H33: =$K$5-$K$6-(0.4*$K$7) -> -520
D34: Vapaa-ajan asunto | E34: 613.52
D35: Talous- ja autotallirakennus | E35: 501.18
D36: Toimistorakennus | E36: 1065.71
D37: Myymälärakennus | E37: 328.36
D38: Teollisuusrakennus | E38: 128.14
D39: Keskussairaalat | E39: 1595.71
D40: Aluesairaalat | E40: 1284.63
D41: Terveyskeskukset ja paikallissairaalat | E41: 1189.54
D42: Kunnallis- ja vanhainkodit ym. | E42: 1045.54
...

Sheet pohja_talous
A2: Hanke: | B2: Esimerkkikaava 1 | D2: Varaus | E2: Kerroin tai %
A3: Laatija: | B3: Esimerkki | D3: Esimerkki | E3: =120/100 -> 1.2
A4: Päivämäärä: | B4: 46073
F6: Sarakkeessa nyt olevat päästöarvot tulevat data-välilehden Päästöt-taulukosta, muokkaa arvot mieluiten suoraan sinne TAI täytä tässä tyhjiä soluja | G6: Alasvetovalikko, saa muokata | J6: Alasvetovalikko, saa muokata
A7: YLÄKATEGORIA | B7: KATEGORIA | C7: OSATEKIJÄ | D7: € | E7: VARAUKSET | F7: PÄÄSTÖT | G7: OSAPUOLI | H7: OHJEET ARVON NOUTOON | I7: OHJEET PÄÄSTÖARVON NOUTOON | J7: PÄÄOMA- VAI KÄYTTÖTALOUS | K7: KERTYMÄN VUODET | L7: KUSTANNUS/TULO | M7: KOONTI
A8: Talonrakentaminen | B8: Esirakentaminen | D8: 0 | E8: =$E$3*D8 -> 0 | F8: =pohja_päästöt!D4 -> 7000 | G8: Tampereen kaupunki | H8: Tieto selvitetään KITIA:lta | J8: Pääomatalous | L8: Kustannus | M8: =IF(L8="Kustannus", -1*D8, D8) -> 0
A9: Talonrakentaminen | B9: Maaperän kunnostaminen | D9: 0 | F9: =pohja_päästöt!D6 -> 10000 | G9: Tampereen kaupunki | H9: Tieto selvitetään KITIA:lta | J9: Pääomatalous | L9: Kustannus | M9: =IF(L9="Kustannus", -1*D9, D9) -> 0
A10: Talonrakentaminen | B10: Rakenteiden muutokset ja purut | D10: 0 | F10: =pohja_päästöt!D8 -> 0 | G10: Tampereen kaupunki | H10: Tieto selvitetään KITIA:lta | J10: Pääomatalous | L10: Kustannus | M10: =IF(L10="Kustannus", -1*D10, D10) -> 0
A11: Talonrakentaminen | B11: Talonrakentaminen | C11: Kaavaillut rakennukset | D11: 2300000 | G11: Tampereen kaupunki | H11: Tieto selvitetään KITIA:lta | J11: Pääomatalous | L11: Kustannus | M11: =IF(L11="Kustannus", -1*D11, D11) -> -2300000
A12: Talonrakentaminen | B12: Palvelutilarakennusten rakentaminen | C12: Uusi palvelutilarakennus | D12: 1000000 | F12: =pohja_päästöt!D19 -> 128000 | G12: Tampereen kaupunki | H12: Tieto selvitetään KITIA:lta | J12: Pääomatalous | L12: Kustannus | M12: =IF(L12="Kustannus", -1*D12, D12) -> -1000000
A13: Talonrakentaminen | B13: Palvelutilarakennusten kunnossapito | D13: 1200000 | G13: Tampereen kaupunki | H13: Tieto selvitetään KITIA:lta | J13: Käyttötalous | K13: 10 | L13: Kustannus | M13: =IF(L13="Kustannus", -1*D13, D13) -> -1200000
A14: Infrarakentaminen | B14: Esirakentaminen | C14: Massanvaihto | D14: 270000 | F14: =pohja_päästöt!D3 -> 138000 | G14: Tampereen kaupunki | H14: Kustannus lasketaan Ihku-laskentapalvelussa | J14: Pääomatalous | L14: Kustannus | M14: =IF(L14="Kustannus", -1*D14, D14) -> -270000
A15: Infrarakentaminen | B15: Maaperän kunnostaminen | C15: Pilaantuneen maan poisto | D15: 400000 | F15: =pohja_päästöt!D5 -> 10000 | G15: Tampereen kaupunki | H15: Kustannus lasketaan Ihku-laskentapalvelussa | J15: Pääomatalous | L15: Kustannus | M15: =IF(L15="Kustannus", -1*D15, D15) -> -400000
A16: Infrarakentaminen | B16: Rakenteiden muutokset ja purut | C16: Putken purku | D16: 7000 | F16: =pohja_päästöt!D7 -> 2000 | G16: Tampereen kaupunki | H16: Kustannus lasketaan Ihku-laskentapalvelussa | J16: Pääomatalous | L16: Kustannus | M16: =IF(L16="Kustannus", -1*D16, D16) -> -7000
A17: Infrarakentaminen | B17: Melusuojat | C17: Meluseinä | D17: 27000 | F17: =pohja_päästöt!D10 -> 138000 | G17: Tampereen kaupunki | H17: Kustannus lasketaan Ihku-laskentapalvelussa | J17: Pääomatalous | L17: Kustannus | M17: =IF(L17="Kustannus", -1*D17, D17) -> -27000
A18: Infrarakentaminen | B18: Ympäristösuojat | C18: Ympäristösuoja | D18: 20000 | G18: Tampereen kaupunki | H18: Kustannus lasketaan Ihku-laskentapalvelussa | J18: Pääomatalous | L18: Kustannus | M18: =IF(L18="Kustannus", -1*D18, D18) -> -20000
A19: Infrarakentaminen | B19: Tie- ja katuverkon rakentaminen | C19: Alueellinen kokoojakatu | D19: =96000 -> 96000 | F19: =pohja_päästöt!D12 -> 237000 | G19: Tampereen kaupunki | H19: Kustannus lasketaan Ihku-laskentapalvelussa | J19: Pääomatalous | L19: Kustannus | M19: =IF(L19="Kustannus", -1*D19, D19) -> -96000
A20: Infrarakentaminen | B20: Kunnallistekniikan rakentaminen | G20: Tampereen kaupunki | H20: Kustannus lasketaan Ihku-laskentapalvelussa | J20: Pääomatalous | L20: Kustannus | M20: =IF(L20="Kustannus", -1*D20, D20) -> 0
A21: Infrarakentaminen | B21: Vesihuolto | C21: Vesihuollon järjestelmä | D21: 170000 | F21: =pohja_päästöt!D15 -> 37000 | G21: Tampereen vesi | H21: Kustannus lasketaan Ihku-laskentapalvelussa | J21: Pääomatalous | L21: Kustannus | M21: =IF(L21="Kustannus", -1*D21, D21) -> -170000
A22: Infrarakentaminen | B22: Energiahuolto | C22: Kaukolämpöjärjestelmä | D22: 55800 | F22: =pohja_päästöt!D16 -> 7000 | G22: Tampereen energia | H22: Kustannus lasketaan Ihku-laskentapalvelussa | J22: Pääomatalous | L22: Kustannus | M22: =IF(L22="Kustannus", -1*D22, D22) -> -55800
A23: Infrarakentaminen | B23: Puistojen ja yleisten alueiden rakentaminen | C23: Puistoaukio | D23: 364800 | F23: =pohja_päästöt!D13 -> 115000 | G23: Tampereen kaupunki | H23: Kustannus lasketaan Ihku-laskentapalvelussa | J23: Pääomatalous | L23: Kustannus | M23: =IF(L23="Kustannus", -1*D23, D23) -> -364800
A24: Infrarakentaminen | B24: Puistojen ja yleisten alueiden rakentaminen | C24: Aluevalaistus | D24: 200000 | F24: =pohja_päästöt!D14 -> 38000 | G24: Tampereen kaupunki | H24: Kustannus lasketaan Ihku-laskentapalvelussa | J24: Pääomatalous | L24: Kustannus | M24: =IF(L24="Kustannus", -1*D24, D24) -> -200000
A25: Infrarakentaminen | B25: Sillat (taitorakenteet) | C25: Alikulkukäytävä | D25: 159000 | F25: =pohja_päästöt!D17 -> 89000 | G25: Tampereen kaupunki | H25: Kustannus lasketaan Ihku-laskentapalvelussa | J25: Pääomatalous | L25: Kustannus | M25: =IF(L25="Kustannus", -1*D25, D25) -> -159000
A26: Infrarakentaminen | B26: Raitiotie | G26: Raitiotie-allianssi | H26: Kustannus saadaan Raitiotie-allianssilta | J26: Pääomatalous | L26: Kustannus | M26: =IF(L26="Kustannus", -1*D26, D26) -> 0
A27: Infrarakentaminen | B27: Pysäköinti | D27: 40000 | G27: Tampereen kaupunki | H27: Kustannus lasketaan pysäköintipolitiikan perusteella | J27: Pääomatalous | L27: Kustannus | M27: =IF(L27="Kustannus", -1*D27, D27) -> -40000
A28: Infrarakentaminen | B28: Tie- ja katuverkon kunnossapito | D28: 41000 | G28: Tampereen kaupunki | J28: Käyttötalous | K28: 50 | L28: Kustannus | M28: =IF(L28="Kustannus", -1*D28, D28) -> -41000
A29: Infrarakentaminen | B29: Kunnallistekniikan kunnossapito | D29: 70000 | G29: Tampereen kaupunki | J29: Käyttötalous | K29: 50 | L29: Kustannus | M29: =IF(L29="Kustannus", -1*D29, D29) -> -70000
A30: Infrarakentaminen | B30: Puistojen ja yleisten alueiden kunnossapito | D30: 91000 | G30: Tampereen kaupunki | J30: Käyttötalous | K30: 50 | L30: Kustannus | M30: =IF(L30="Kustannus", -1*D30, D30) -> -91000
A31: Maanhankinta | B31: Maan osto | D31: 1200000 | G31: Tampereen kaupunki | H31: Kaupungin maanhankintapäällikön konsultointi | J31: Pääomatalous | L31: Kustannus | M31: =IF(L31="Kustannus", -1*D31, D31) -> -1200000
A32: Maanhankinta | B32: Maan lunastus | D32: 110000 | G32: Tampereen kaupunki | H32: Kaupungin maanhankintapäällikön konsultointi | J32: Pääomatalous | L32: Kustannus | M32: =IF(L32="Kustannus", -1*D32, D32) -> -110000
A33: Maan myynti tai vuokraus | B33: Maan myynti | D33: =SUM(data!K17:K22) -> 2300000 | G33: Tampereen kaupunki | H33: Tieto selvitetään KITIA:lta. Tieto perustuu vyöhykehinnastoihin. | J33: Pääomatalous | L33: Tulo | M33: =IF(L33="Kustannus", -1*D33, D33) -> 2300000
A34: Maan myynti tai vuokraus | B34: Maan vuokraus | D34: 1500000 | G34: Tampereen kaupunki | H34: Tieto selvitetään KITIA:lta. Tieto perustuu arvioon tulevasta arvonnoususta ja maan käyttötarkoitukseen. | J34: Käyttötalous | K34: 50 | L34: Tulo | M34: =IF(L34="Kustannus", -1*D34, D34) -> 1500000
A35: Maankäyttötulot | B35: Maankäyttömaksut | D35: =SUM(D15:D25) -> 1499600 | G35: Tampereen kaupunki | H35: Tieto selvitetään KITIA:lta. Maankäyttömaksujen tulee kattaa vähintään välittömät infran investointikustannukset. | J35: Pääomatalous | L35: Tulo | M35: =IF(L35="Kustannus", -1*D35, D35) -> 1499600
A36: Verotulot | B36: Kunnallisvero | D36: =data!E28 -> 2280000 | G36: Tampereen kaupunki | J36: Käyttötalous | K36: 25 | L36: Tulo | M36: =IF(L36="Kustannus", -1*D36, D36) -> 2280000
A37: Verotulot | B37: Kiinteistövero | D37: =(3000*data!E33)*(data!E21/100)*25 -> 720975 | G37: Tampereen kaupunki | J37: Käyttötalous | K37: 25 | L37: Tulo | M37: =IF(L37="Kustannus", -1*D37, D37) -> 720975
A38: Verkostomaksut | B38: Käyttömaksut, vesi | D38: =795*1000 -> 795000 | G38: Tampereen vesi | H38: Tampereen vedeltä saadaan tulot hinnastoon perustuen. | J38: Käyttötalous | K38: 25 | L38: Tulo | M38: =IF(L38="Kustannus", -1*D38, D38) -> 795000
A39: Verkostomaksut | B39: Käyttömaksut, energia | D39: =850*1000 -> 850000 | G39: Tampereen energia | H39: Tampereen energialta saadaan tulot hinnastoon perustuen. | J39: Käyttötalous | K39: 25 | L39: Tulo | M39: =IF(L39="Kustannus", -1*D39, D39) -> 850000
A40: Verkostomaksut | B40: Liittymismaksut, vesi | D40: =5400*25 -> 135000 | G40: Tampereen vesi | H40: Tampereen vedeltä saadaan tulot hinnastoon perustuen. | J40: Pääomatalous | L40: Tulo | M40: =IF(L40="Kustannus", -1*D40, D40) -> 135000
A41: Verkostomaksut | B41: Liittymismaksut, energia | D41: =8157*25 -> 203925 | G41: Tampereen energia | H41: Tampereen energialta saadaan tulot hinnastoon perustuen. | J41: Pääomatalous | L41: Tulo | M41: =IF(L41="Kustannus", -1*D41, D41) -> 203925

Sheet pohja_päästöt
B2: Päästöluokka | C2: Tarkennettu luokka | D2: Päästöt | E2: Prosentti kokonaispäästöistä (%) | F2: Päästöjen saanti | G2: Muodostuminen | H2: Tekninen
B3: Rakentamiskelpoiseksi saattaminen | C3: Esirakentaminen | D3: 138000 | E3: =D3/SUM($D$3:$D$20) -> 0.14435146 | F3: Ihkusta (infra) | G3: Hankeosittain tai todennäköisemmin manuaalisesti poimitaan pääotsikon mukaan
B4: Rakentamiskelpoiseksi saattaminen | C4: Esirakentaminen (talo) | D4: 7000 | E4: =D4/SUM($D$3:$D$20) -> 0.0073221757 | F4: Syke CO2 ? | I4: Saadaanko KITIA:lta, huomioidaanko itsessään?
B5: Rakentamiskelpoiseksi saattaminen | C5: Maaperän kunnostaminen | D5: 10000 | E5: =D5/SUM($D$3:$D$20) -> 0.010460251 | F5: Ihkusta (infra)
B6: Rakentamiskelpoiseksi saattaminen | C6: Maaperän kunnostaminen (talo) | D6: 10000 | E6: =D6/SUM($D$3:$D$20) -> 0.010460251 | F6: Syke CO2 ? | I6: Saadaanko KITIA:lta, huomioidaanko itsessään?
B7: Rakentamiskelpoiseksi saattaminen | C7: Rakenteiden muutokset ja purut | D7: 2000 | E7: =D7/SUM($D$3:$D$20) -> 0.0020920502 | F7: Ihkusta (infra)
B8: Rakentamiskelpoiseksi saattaminen | C8: Rakenteiden muutokset ja purut (talo) | D8: 0 | E8: =D8/SUM($D$3:$D$20) -> 0 | F8: Syke CO2 ? | I8: Saadaanko KITIA:lta, huomioidaanko itsessään?
B9: Rakentamiskelpoiseksi saattaminen | C9: Johtosiirrot | D9: 0 | E9: =D9/SUM($D$3:$D$20) -> 0
B10: Katujen rakentaminen | C10: Melusuojat | D10: 138000 | E10: =D10/SUM($D$3:$D$20) -> 0.14435146 | F10: Ihkusta
B11: Katujen rakentaminen | C11: Ympäristösuojat | D11: 0 | E11: =D11/SUM($D$3:$D$20) -> 0 | F11: Ihkusta
B12: Katujen rakentaminen | C12: Tie- ja katuverkon rakentaminen | D12: 237000 | E12: =D12/SUM($D$3:$D$20) -> 0.24790795 | F12: Ihkusta
B13: Puistojen rakentaminen | C13: Puistojen ja yleisten alueiden rakentaminen | D13: 115000 | E13: =D13/SUM($D$3:$D$20) -> 0.12029289 | F13: Ihkusta
B14: Puistojen rakentaminen | C14: Aluevalaistus | D14: 38000 | E14: =D14/SUM($D$3:$D$20) -> 0.039748954
B15: Vesihuolto | C15: Vesihuolto | D15: 37000 | E15: =D15/SUM($D$3:$D$20) -> 0.038702929 | F15: Ihkusta
B16: Energiahuolto | C16: Energiahuolto | D16: 7000 | E16: =D16/SUM($D$3:$D$20) -> 0.0073221757 | F16: Ihkusta
B17: Sillat | C17: Sillat | D17: 89000 | E17: =D17/SUM($D$3:$D$20) -> 0.093096234 | F17: Ihkusta
B18: Satama | D18: 0 | E18: =D18/SUM($D$3:$D$20) -> 0 | F18: Syke CO2 ? | I18: SYKE_Päästöt-sivulla mitään soveltuvaa? Liikennerakennus
B19: Julkisten palvelutilojen rakentaminen | C19: Palvelutilarakennusten rakentaminen | D19: =data!S7*1000 -> 128000 | E19: =D19/SUM($D$3:$D$20) -> 0.13389121 | F19: Syke CO2 | H19: SYKE_Päästöt!G5 | I19: KITIA:lta kysyttävää, lasketteko?
B20: Soutu- ja melontakeskus | D20: 0 | E20: =D20/SUM($D$3:$D$20) -> 0 | F20: Syke CO2 ? | I20: SYKE_Päästöt-sivulla mitään soveltuvaa? Urheiluhalli?

Sheet yhteenveto
